Workbook

Sheet Inputs
B1: LEED v4.1 RETROFIT SAVINGS CALCULATOR
B2: Based on ASHRAE 90.1-2019 Baseline | EPA WaterSense Standards | LEED v4.1 BD+C Rating System
B4: SECTION 1 — BUILDING INFORMATION
B5: Building Name / Project ID | C5: Casa Cortile Retrofit | E5: Source: ASHRAE 90.1-2019 §5
B6: Building Type | C6: Office/Commercial | E6: Options: Office, Retail, Multifamily, School, Warehouse
B7: Gross Floor Area | C7: 8500 | D7: sq ft | E7: Total conditioned area
B8: Number of Stories | C8: 2 | D8: floors
B9: Year Built | C9: 1998 | E9: Pre-2000 = higher baseline energy use
B10: Climate Zone (ASHRAE 90.1) | C10: 2A | E10: Dallas-Fort Worth = Zone 2A (Hot-Humid)
B11: Occupancy Hours per Week | C11: 55 | D11: hrs/wk | E11: Typical office: 50-60 hrs/wk
B12: Number of Occupants | C12: 45 | D12: people | E12: Used for water demand calculation
B13: Annual Energy Cost (current) | C13: 28400 | D13: $/yr | E13: From utility bills — pre-retrofit baseline
B14: Local Electricity Rate | C14: 0.12 | D14: $/kWh | E14: DFW avg: ~$0.12/kWh (2024)
B15: Local Gas Rate | C15: 0.85 | D15: $/therm | E15: DFW avg: ~$0.85/therm (2024)
B16: Annual Water Cost (current) | C16: 4200 | D16: $/yr | E16: From utility bills — pre-retrofit baseline
B17: Local Water Rate | C17: 0.006 | D17: $/gal | E17: DFW avg: ~$0.006/gal (2024)
B19: SECTION 2 — CURRENT BUILDING SYSTEMS (BASELINE)
B20: Current HVAC System Type | C20: Packaged RTU (pre-2010) | E20: Baseline EER: ~10
B21: Current HVAC SEER/EER | C21: 10 | E21: ASHRAE 90.1-2019 minimum = 15 SEER for Zone 2A
B22: Current Lighting Type | C22: T8 Fluorescent | E22: Baseline: 1.1 W/sq ft per ASHRAE 90.1 Table 9.6
B23: Current Lighting Power Density | C23: 1.1 | D23: W/sq ft | E23: ASHRAE 90.1 office baseline
B24: Current Roof Insulation (R-value) | C24: 20 | E24: ASHRAE 90.1-2019 Zone 2A minimum = R-20 ci
B25: Current Window U-Factor | C25: 0.65 | E25: ASHRAE 90.1-2019 Zone 2A max = 0.40
B26: Current Toilet Flush Volume | C26: 1.6 | D26: gpf | E26: Pre-1992 standard; EPA WaterSense max = 1.28 gpf
B27: Current Urinal Flush Volume | C27: 1 | D27: gpf | E27: EPA WaterSense max = 0.5 gpf
B28: Current Lavatory Flow Rate | C28: 2.2 | D28: gpm | E28: EPA WaterSense max = 1.5 gpm
B29: Current Kitchen Faucet Flow | C29: 2.2 | D29: gpm | E29: EPA WaterSense max = 1.8 gpm
B30: Has Rooftop Solar PV? | C30: No | E30: Enter Yes or No
B32: SECTION 3 — PROPOSED RETROFIT MEASURES
B33: Upgrade HVAC to High-Efficiency? | C33: Yes | E33: Enter Yes or No
B34: Proposed HVAC SEER/EER | C34: 20 | E34: High-efficiency unit: 18-22 SEER
B35: Upgrade Lighting to LED? | C35: Yes | E35: Enter Yes or No
B36: Proposed LED Power Density | C36: 0.6 | D36: W/sq ft | E36: LEED target: ≤0.6 W/sq ft for office
B37: Upgrade Roof Insulation? | C37: Yes | E37: Enter Yes or No
B38: Proposed Roof R-value | C38: 30 | E38: ASHRAE 90.1 enhanced: R-30 ci
B39: Upgrade Windows? | C39: Yes | E39: Enter Yes or No
B40: Proposed Window U-Factor | C40: 0.35 | E40: High-performance glazing
B41: Install WaterSense Toilets? | C41: Yes | E41: 1.28 gpf dual-flush
B42: Install WaterSense Lavatory Faucets? | C42: Yes | E42: 1.5 gpm aerators
B43: Install WaterSense Urinals? | C43: Yes | E43: 0.5 gpf or non-water
...

Sheet Energy Savings
B1: ENERGY SAVINGS ANALYSIS — ASHRAE 90.1-2019 BASELINE
B3: Retrofit Measure | C3: Baseline Energy Use | D3: Post-Retrofit Use | E3: Annual kBtu Saved | F3: Annual $ Saved
B4: HVAC System Upgrade (High-Efficiency) | C4: =ROUND((Inputs!C13/Inputs!C14)*3.412*0.4,0) -> 323003 | D4: =IF(Inputs!C33="Yes",ROUND(C4*(Inputs!C21/Inputs!C34),0),C4) -> 161502 | E4: =C4-D4 -> 161501 | F4: =ROUND(E4/3.412*Inputs!C14,0) -> 5680
B5: Lighting Upgrade (LED Retrofit) | C5: =ROUND(Inputs!C23*Inputs!C7*(Inputs!C11*52)/1000*3.412,0) -> 91240 | D5: =IF(Inputs!C35="Yes",ROUND(Inputs!C36*Inputs!C7*(Inputs!C11*52)/1000*3.412,0),C5) -> 49767 | E5: =C5-D5 -> 41473 | F5: =ROUND(E5/3.412*Inputs!C14,0) -> 1459
B6: Roof Insulation Upgrade (R-20 → R-30) | C6: =ROUND((Inputs!C13/Inputs!C14)*3.412*0.1,0) -> 80751 | D6: =IF(Inputs!C37="Yes",ROUND(C6*(1-(1-Inputs!C24/Inputs!C38)*0.5),0),C6) -> 67293 | E6: =C6-D6 -> 13458 | F6: =ROUND(E6/3.412*Inputs!C14,0) -> 473
B7: Window Upgrade (U-0.65 → U-0.35 High Performance) | C7: =ROUND((Inputs!C13/Inputs!C14)*3.412*0.08,0) -> 64601 | D7: =IF(Inputs!C39="Yes",ROUND(C7*(Inputs!C40/Inputs!C25),0),C7) -> 34785 | E7: =C7-D7 -> 29816 | F7: =ROUND(E7/3.412*Inputs!C14,0) -> 1049
B8: Rooftop Solar PV Generation | C8: 0 | D8: 0 | E8: =IF(Inputs!C44="Yes",ROUND(Inputs!C45*1460*3.412,0),0) -> 149446 | F8: =ROUND(E8/3.412*Inputs!C14,0) -> 5256
B10: TOTAL ENERGY SAVINGS | E10: =SUM(E4:E8) -> 395694 | F10: =SUM(F4:F8) -> 13917
B11: Energy Cost Reduction (%) | F11: =IFERROR(F10/Inputs!C13,0) -> 0.49003521
B13: Methodology: HVAC savings based on SEER ratio per ASHRAE 90.1-2019 §6. Lighting per Table 9.6.1 LPD. Envelope per §5.5 prescriptive path. Solar per NREL PVWatts (DFW: 4.0 peak sun hrs/day).

Sheet Water Savings
B1: WATER SAVINGS ANALYSIS — EPA WATERSENSE BASELINE
B3: Fixture Type | C3: Current (gpf/gpm) | D3: WaterSense (gpf/gpm) | E3: Annual gal Saved | F3: Annual $ Saved
B4: Toilets (Dual-Flush WaterSense) | C4: =Inputs!C26 -> 1.6 | D4: =IF(Inputs!C41="Yes",1.28,Inputs!C26) -> 1.28 | E4: =ROUND((C4-D4)*3*Inputs!C12*260,0) -> 11232 | F4: =ROUND(E4*Inputs!C17,0) -> 67
B5: Urinals (WaterSense 0.5 gpf) | C5: =Inputs!C27 -> 1 | D5: =IF(Inputs!C43="Yes",0.5,Inputs!C27) -> 0.5 | E5: =ROUND((C5-D5)*2*(Inputs!C12*0.5)*260,0) -> 5850 | F5: =ROUND(E5*Inputs!C17,0) -> 35
B6: Lavatory Faucets (1.5 gpm aerators) | C6: =Inputs!C28 -> 2.2 | D6: =IF(Inputs!C42="Yes",1.5,Inputs!C28) -> 1.5 | E6: =ROUND((C6-D6)*0.5*3*Inputs!C12*260,0) -> 12285 | F6: =ROUND(E6*Inputs!C17,0) -> 74
B7: Kitchen/Break Room Faucets (1.8 gpm) | C7: =Inputs!C29 -> 2.2 | D7: =IF(Inputs!C42="Yes",1.8,Inputs!C29) -> 1.8 | E7: =ROUND((C7-D7)*15*Inputs!C12*260/60,0) -> 1170 | F7: =ROUND(E7*Inputs!C17,0) -> 7
B9: TOTAL WATER SAVINGS | E9: =SUM(E4:E7) -> 30537 | F9: =SUM(F4:F7) -> 183
B10: Water Use Reduction (%) | F10: =IFERROR(F9/Inputs!C16,0) -> 0.043571429
B12: Methodology: EPA WaterSense fixture baselines. Occupancy: 260 workdays/yr. Toilet: 3 uses/person/day. Urinal: 2 uses/person/day (50% occupancy). Lavatory: 3 uses × 0.5 min/use. Kitchen: 15 min/day.

Sheet LEED Points
B1: LEED v4.1 BD+C — POINTS ESTIMATOR
B2: Rating: Building Design and Construction (BD+C) — New Construction & Major Renovation
B4: LEED Credit | C4: Max Pts Available | D4: Estimated Pts Achieved | E4: Basis for Estimate
B5: SUSTAINABLE SITES (SS)
B6: SS Credit: Rainwater Management | C6: 2 | D6: 1 | E6: Single retention strategy assumed
B7: SS Credit: Heat Island Reduction | C7: 2 | D7: =IF(Inputs!C44="Yes",2,1) -> 2 | E7: Cool roof + solar = 2 pts; roof only = 1 pt
B8: SS Credit: Light Pollution Reduction | C8: 1 | D8: 1 | E8: Assumed compliant fixture selection
B10: WATER EFFICIENCY (WE)
B11: WE Prereq: Indoor Water Use Reduction | C11: 0 | D11: =IF(AND(Inputs!C41="Yes",Inputs!C42="Yes",Inputs!C43="Yes"),0,0) -> 0 | E11: Prerequisite — WaterSense toilets+faucets+urinals required
B12: WE Credit: Indoor Water Use Reduction | C12: 6 | D12: =IF('Water Savings'!F10>=0.4,6,IF('Water Savings'!F10>=0.3,4,IF('Water Savings'!F10>=0.2,2,0))) -> 0 | E12: 6 pts @ ≥40% reduction; 4 pts @ ≥30%; 2 pts @ ≥20%
B13: WE Credit: Outdoor Water Use Reduction | C13: 2 | D13: 1 | E13: Drought-tolerant landscaping assumed
B15: ENERGY & ATMOSPHERE (EA)
B16: EA Prereq: Fundamental Commissioning | C16: 0 | D16: 0 | E16: Prereq — no points, required for certification
B17: EA Credit: Optimize Energy Performance | C17: 18 | D17: =IF('Energy Savings'!F11>=0.5,18,IF('Energy Savings'!F11>=0.4,14,IF('Energy Savings'!F11>=0.3,10,IF('Energy Savings'!F11>=0.2,6,IF('Energy Savings'!F11>=0.1,2,0))))) -> 14 | E17: 18 pts @ 50%+ savings; 14 pts @ 40%; 10 pts @ 30%; 6 pts @ 20%
B18: EA Credit: Advanced Energy Metering | C18: 1 | D18: 1 | E18: Assumed smart metering installed with retrofit
B19: EA Credit: Renewable Energy Production | C19: 3 | D19: =IF(Inputs!C44="Yes",IF(Inputs!C45>=30,3,IF(Inputs!C45>=20,2,1)),0) -> 3 | E19: 3 pts @ ≥30 kW; 2 pts @ ≥20 kW; 1 pt @ any solar
B20: EA Credit: Enhanced Commissioning | C20: 6 | D20: 2 | E20: Enhanced Cx with monitoring-based Cx (2 pts assumed)
B22: MATERIALS & RESOURCES (MR)
B23: MR Credit: Construction Waste Management | C23: 2 | D23: 1 | E23: 50%+ diversion assumed with recycling plan
B24: MR Credit: Low-Emitting Materials | C24: 3 | D24: 2 | E24: Low-VOC paints, adhesives, flooring specified
B26: INDOOR ENVIRONMENTAL QUALITY (EQ)
B27: EQ Credit: Enhanced IAQ Strategies | C27: 2 | D27: 1 | E27: MERV-13 filtration + additional air monitoring
B28: EQ Credit: Thermal Comfort | C28: 1 | D28: =IF(Inputs!C33="Yes",1,0) -> 1 | E28: New HVAC enables compliant thermal comfort per ASHRAE 55
B29: EQ Credit: Interior Lighting Quality | C29: 2 | D29: =IF(Inputs!C35="Yes",2,0) -> 2 | E29: LED retrofit enables tunable/dimmable lighting control
B30: EQ Credit: Daylight | C30: 3 | D30: =IF(Inputs!C39="Yes",2,0) -> 2 | E30: Window upgrade improves VLT for daylighting credit
B32: INNOVATION (IN)
B33: IN Credit: Innovation | C33: 5 | D33: 2 | E33: 2 innovative strategies assumed in retrofit design
B34: IN Credit: LEED Accredited Professional | C34: 1 | D34: 1 | E34: LEED GA on project team (Suhas Ravi, LEED GA)
B36: REGIONAL PRIORITY (RP) — DALLAS-FORT WORTH, TX
B37: RP Credit: Water Efficiency (DFW priority) | C37: 4 | D37: =IF('Water Savings'!F10>=0.3,1,0) -> 0 | E37: DFW regional priority: water conservation
B38: RP Credit: Energy Optimization (DFW) | C38: 4 | D38: =IF('Energy Savings'!F11>=0.3,1,0) -> 1 | E38: DFW regional priority: energy performance
B40: TOTAL ESTIMATED LEED POINTS | C40: 110 | D40: =SUM(D6:D8,D11:D13,D16:D20,D23:D24,D27:D30,D33:D34,D37:D38) -> 38
B41: Projected Certification Level | D41: =IF(D40>=80,"PLATINUM",IF(D40>=60,"GOLD",IF(D40>=50,"SILVER",IF(D40>=40,"CERTIFIED","Not Certified")))) -> Not Certified
B43: Thresholds: Certified = 40–49 pts | Silver = 50–59 pts | Gold = 60–79 pts | Platinum = 80+ pts

Sheet Summary Report
B1: LEED RETROFIT SUMMARY REPORT
B2: =Inputs!C5 -> Casa Cortile Retrofit
B4: PROJECT INFORMATION
B5: Building Type | C5: =Inputs!C6 -> Office/Commercial
B6: Gross Floor Area (sq ft) | C6: =Inputs!C7 -> 8500
B7: Climate Zone | C7: =Inputs!C10 -> 2A
B8: Current Annual Energy Cost | C8: =Inputs!C13 -> 28400
B9: Current Annual Water Cost | C9: =Inputs!C16 -> 4200
B11: ENERGY SAVINGS
B12: Total Annual kBtu Saved | C12: ='Energy Savings'!E10 -> 395694
B13: Annual Energy Cost Savings | C13: ='Energy Savings'!F10 -> 13917
B14: Energy Reduction (%) | C14: ='Energy Savings'!F11 -> 0.49003521
B16: WATER SAVINGS
B17: Total Annual Gallons Saved | C17: ='Water Savings'!E9 -> 30537
B18: Annual Water Cost Savings | C18: ='Water Savings'!F9 -> 183
B19: Water Use Reduction (%) | C19: ='Water Savings'!F10 -> 0.043571429
B21: COMBINED ANNUAL SAVINGS
B22: Total Annual Cost Savings | C22: ='Energy Savings'!F10+'Water Savings'!F9 -> 14100
B23: Total Savings as % of Bills | C23: =('Energy Savings'!F10+'Water Savings'!F9)/(Inputs!C13+Inputs!C16) -> 0.43251534
B25: LEED CERTIFICATION
B26: Total Estimated LEED Points | C26: ='LEED Points'!D40 -> 38
B27: Projected Certification Level | C27: ='LEED Points'!D41 -> Not Certified
B28: Points to Next Level | C28: =IF('LEED Points'!D40<40,40-'LEED Points'!D40,IF('LEED Points'!D40<50,50-'LEED Points'!D40,IF('LEED Points'!D40<60,60-'LEED Points'!D40,IF('LEED Points'!D40<80,80-'LEED Points'!D40,0)))) -> 2
B30: RETROFIT MEASURES SELECTED
B31: HVAC High-Efficiency Upgrade | C31: =IF(Inputs!C33="Yes","YES — "&Inputs!C34&" SEER","Not selected") -> YES — 20 SEER
B32: LED Lighting Retrofit | C32: =IF(Inputs!C35="Yes","YES — "&Inputs!C36&" W/sq ft","Not selected") -> YES — 0.6 W/sq ft
B33: Roof Insulation Upgrade | C33: =IF(Inputs!C37="Yes","YES — R-"&Inputs!C38,"Not selected") -> YES — R-30
B34: High-Performance Windows | C34: =IF(Inputs!C39="Yes","YES — U-"&Inputs!C40,"Not selected") -> YES — U-0.35
B35: WaterSense Toilets | C35: =IF(Inputs!C41="Yes","YES — 1.28 gpf","Not selected") -> YES — 1.28 gpf
B36: WaterSense Faucets | C36: =IF(Inputs!C42="Yes","YES — 1.5 gpm","Not selected") -> YES — 1.5 gpm
B37: WaterSense Urinals | C37: =IF(Inputs!C43="Yes","YES — 0.5 gpf","Not selected") -> YES — 0.5 gpf
B38: Rooftop Solar PV | C38: =IF(Inputs!C44="Yes","YES — "&Inputs!C45&" kW DC","Not selected") -> YES — 30 kW DC
B41: Generated by: LEED v4.1 Retrofit Savings Calculator | Suhas Ravi, CMIT, LEED GA | linkedin.com/in/suhasravi
